<?xml version="1.0" ?>
<sdf version="1.4">
  <model name="uarm">
    <static>0</static>
    <link name='table_link'>
      <pose>0 0 0.001 0 0 0</pose>
      <inertial>
        <mass>50.55</mass>
        <inertia>
          <ixx>1</ixx>
          <ixy>1</ixy>
          <ixz>1</ixz>
          <iyy>1</iyy>
          <iyz>1</iyz>
          <izz>1</izz>
        </inertia>
      </inertial>
      <collision name='collision'>
        <geometry>
          <cylinder>
            <radius> 0.1 </radius>
            <length> 0.002 </length>
          </cylinder>
        </geometry>
        <max_contacts>10</max_contacts>
        <surface>
          <bounce/>
          <friction>
            <ode/>
          </friction>
          <contact>
            <ode/>
          </contact>
        </surface>
      </collision>
      <visual name='visual'>
        <geometry>
          <cylinder>
            <radius> 0.1 </radius>
            <length> 0.002 </length>
          </cylinder>
        </geometry>
        <material>
          <script>
            <uri>file://media/materials/scripts/gazebo.material</uri>
            <name>Gazebo/Grey</name>
          </script>
        </material>
      </visual>
      <self_collide>0</self_collide>
    </link>
    <link name='base_center'>
      <pose>0 0 0.012 0 0 0</pose>
      <inertial>
        <mass>1.55</mass>
        <inertia>
          <ixx>1</ixx>
          <ixy>0</ixy>
          <ixz>0</ixz>
          <iyy>1</iyy>
          <iyz>0</iyz>
          <izz>1</izz>
        </inertia>
      </inertial>
      <collision name='collision'>
        <geometry>
          <cylinder>
            <radius> 0.04 </radius>
            <length> 0.02 </length>
          </cylinder>
        </geometry>
        <max_contacts>10</max_contacts>
        <surface>
          <bounce/>
          <friction>
            <ode/>
          </friction>
          <contact>
            <ode/>
          </contact>
        </surface>
      </collision>
      <visual name='visual'>
        <geometry>
          <cylinder>
            <radius> 0.04 </radius>
            <length> 0.02 </length>
          </cylinder>
        </geometry>
        <material>
          <script>
            <uri>file://media/materials/scripts/gazebo.material</uri>
            <name>Gazebo/Grey</name>
          </script>
        </material>
      </visual>
      <self_collide>0</self_collide>
    </link>
    <link name="base_l">
      <pose> 0 0 0 0 0 0 </pose>
      <inertial>
        <mass>0.0288</mass>
        <inertia>
          <ixx>0.0051</ixx>
          <iyy>0.0051</iyy>
          <izz>0.0090</izz>
          <ixy>0</ixy>
          <ixz>0</ixz>
          <iyz>0</iyz>
        </inertia>
      </inertial>
      <collision name="collision">
        <pose>0 0 0 0 0 0</pose>
        <geometry>
          <mesh>
            <uri>model://uarm/meshes/base_l.dae</uri>
          </mesh>
        </geometry>
      </collision>
      <visual name="visual">
        <pose>0 0 0 0 0 0</pose>
        <geometry>
          <mesh>
            <uri>model://uarm/meshes/base_l.dae</uri>
          </mesh>
        </geometry>
      </visual>
      <self_collide>0</self_collide>
    </link>
    <link name="base_r">
      <pose>0 0 0 0 0 0</pose>
      <inertial>
        <mass>0.024</mass>
        <inertia>
          <ixx>0.0051</ixx>
          <iyy>0.0051</iyy>
          <izz>0.0090</izz>
          <ixy>0</ixy>
          <ixz>0</ixz>
          <iyz>0</iyz>
        </inertia>
      </inertial>
      <collision name="collision">
        <pose>0 0 0 0 0 0</pose>
        <geometry>
          <mesh>
            <uri>model://uarm/meshes/base_r.dae</uri>
          </mesh>
        </geometry>
      </collision>
      <visual name="visual">
        <pose>0 0 0 0 0 0</pose>
        <geometry>
          <mesh>
            <uri>model://uarm/meshes/base_r.dae</uri>
          </mesh>
        </geometry>
      </visual>
      <self_collide>0</self_collide>
    </link>
    <link name="big_under_arm_l">
      <pose>0 0 0 0 0 0</pose>
      <inertial>
        <mass>0.0276</mass>
        <pose> -0.008 -0.015 0.13 0 0 0</pose>
        <inertia>
          <ixx>0.0051</ixx>
          <iyy>0.0051</iyy>
          <izz>0.0090</izz>
          <ixy>0</ixy>
          <ixz>0</ixz>
          <iyz>0</iyz>
        </inertia>
      </inertial>
      <collision name="collision">
        <pose>0 0 0 0 0 0</pose>
        <geometry>
          <mesh>
            <uri>model://uarm/meshes/big_under_arm_l.dae</uri>
          </mesh>
        </geometry>
      </collision>
      <visual name="visual">
        <pose>0 0 0 0 0 0</pose>
        <geometry>
          <mesh>
            <uri>model://uarm/meshes/big_under_arm_l.dae</uri>
          </mesh>
        </geometry>
      </visual>
    </link>
    <link name="big_under_arm_r">
      <pose>0 0 0 0 0 0</pose>
      <inertial>
        <mass>0.0276</mass>
        <pose> -0.008 0.015 0.13 0 0 0</pose>
        <inertia>
          <ixx>0.0051</ixx>
          <iyy>0.0051</iyy>
          <izz>0.0090</izz>
          <ixy>0</ixy>
          <ixz>0</ixz>
          <iyz>0</iyz>
        </inertia>
      </inertial>
      <collision name="collision">
        <pose>0 0 0 0 0 0</pose>
        <geometry>
          <mesh>
            <uri>model://uarm/meshes/big_under_arm_r.dae</uri>
          </mesh>
        </geometry>
      </collision>
      <visual name="visual">
        <pose>0 0 0 0 0 0</pose>
        <geometry>
          <mesh>
            <uri>model://uarm/meshes/big_under_arm_r.dae</uri>
          </mesh>
        </geometry>
      </visual>
      <self_collide>0</self_collide>
    </link>
    <link name="shoulder_l">
      <pose>0 0 0 0 0 0</pose>
      <inertial>
        <mass>0.0108</mass>
        <pose> 0 -0.01 0.09 0 0 0</pose>
        <inertia>
          <ixx>0.0051</ixx>
          <iyy>0.0051</iyy>
          <izz>0.0090</izz>
          <ixy>0</ixy>
          <ixz>0</ixz>
          <iyz>0</iyz>
        </inertia>
      </inertial>
      <collision name="collision">
        <pose>0 0 0 0 0 0</pose>
        <geometry>
          <mesh>
            <uri>model://uarm/meshes/shoulder_l.dae</uri>
          </mesh>
        </geometry>
      </collision>
      <visual name="visual">
        <pose>0 0 0 0 0 0</pose>
        <geometry>
          <mesh>
            <uri>model://uarm/meshes/shoulder_l.dae</uri>
          </mesh>
        </geometry>
      </visual>
      <self_collide>0</self_collide>
    </link>
    <link name="shoulder_r">
      <pose>0 0 0 0 0 0</pose>
      <inertial>
        <mass>0.0108</mass>
        <pose> 0 0.02 0.09 0 0 0</pose>
        <inertia>
          <ixx>0.0051</ixx>
          <iyy>0.0051</iyy>
          <izz>0.0090</izz>
          <ixy>0</ixy>
          <ixz>0</ixz>
          <iyz>0</iyz>
        </inertia>
      </inertial>
      <collision name="collision">
        <pose>0 0 0 0 0 0</pose>
        <geometry>
          <mesh>
            <uri>model://uarm/meshes/shoulder_r.dae</uri>
          </mesh>
        </geometry>
      </collision>
      <visual name="visual">
        <pose>0 0 0 0 0 0</pose>
        <geometry>
          <mesh>
            <uri>model://uarm/meshes/shoulder_r.dae</uri>
          </mesh>
        </geometry>
      </visual>
      <self_collide>0</self_collide>
    </link>
    <link name="small_under_arm_l">
      <pose>0 0 0 0 0 0</pose>
      <inertial>
        <mass>0.012</mass>
        <pose> 0.038 -0.03 0.165 0 0 0</pose>
        <inertia>
          <ixx>0.0051</ixx>
          <iyy>0.0051</iyy>
          <izz>0.0090</izz>
          <ixy>0</ixy>
          <ixz>0</ixz>
          <iyz>0</iyz>
        </inertia>
      </inertial>
      <collision name="collision">
        <pose>0 0 0 0 0 0</pose>
        <geometry>
          <mesh>
            <uri>model://uarm/meshes/small_under_arm_l.dae</uri>
          </mesh>
        </geometry>
      </collision>
      <visual name="visual">
        <pose>0 0 0 0 0 0</pose>
        <geometry>
          <mesh>
            <uri>model://uarm/meshes/small_under_arm_l.dae</uri>
          </mesh>
        </geometry>
      </visual>
      <self_collide>0</self_collide>
    </link>
    <link name="small_under_arm_r">
      <pose>0 0 0 0 0 0</pose>
      <inertial>
        <mass>0.0108</mass>
        <pose> 0.042 -0.002 0.165 0 0 0</pose>
        <inertia>
          <ixx>0.0051</ixx>
          <iyy>0.0051</iyy>
          <izz>0.0090</izz>
          <ixy>0</ixy>
          <ixz>0</ixz>
          <iyz>0</iyz>
        </inertia>
      </inertial>
      <collision name="collision">
        <pose>0 0 0 0 0 0</pose>
        <geometry>
          <mesh>
            <uri>model://uarm/meshes/small_under_arm_r.dae</uri>
          </mesh>
        </geometry>
      </collision>
      <visual name="visual">
        <pose>0 0 0 0 0 0</pose>
        <geometry>
          <mesh>
            <uri>model://uarm/meshes/small_under_arm_r.dae</uri>
          </mesh>
        </geometry>
      </visual>
      <self_collide>0</self_collide>
    </link>
    <link name="elbow">
      <pose>0 0 0 0 0 0</pose>
      <inertial>
        <mass>0.0096</mass>
        <pose> 0.028 -0.02 0.235 0 0 0</pose>
        <inertia>
          <ixx>0.0051</ixx>
          <iyy>0.0051</iyy>
          <izz>0.0090</izz>
          <ixy>0</ixy>
          <ixz>0</ixz>
          <iyz>0</iyz>
        </inertia>
      </inertial>
      <collision name="collision">
        <pose>0 0 0 0 0 0</pose>
        <geometry>
          <mesh>
            <uri>model://uarm/meshes/elbow.dae</uri>
          </mesh>
        </geometry>
      </collision>
      <visual name="visual">
        <pose>0 0 0 0 0 0</pose>
        <geometry>
          <mesh>
            <uri>model://uarm/meshes/elbow.dae</uri>
          </mesh>
        </geometry>
      </visual>
      <self_collide>0</self_collide>
    </link>    
    <link name="big_fore_arm_l">
      <pose>0 0 0 0 0 0</pose>
      <inertial>
        <mass>0.0276</mass>
        <pose> -0.023 -0.007 0.2 0 0 0</pose>
        <inertia>
          <ixx>0.0051</ixx>
          <iyy>0.0051</iyy>
          <izz>0.0090</izz>
          <ixy>0</ixy>
          <ixz>0</ixz>
          <iyz>0</iyz>
        </inertia>
      </inertial>
      <collision name="collision">
        <pose>0 0 0 0 0 0</pose>
        <geometry>
          <mesh>
            <uri>model://uarm/meshes/big_fore_arm_l.dae</uri>
          </mesh>
        </geometry>
      </collision>
      <visual name="visual">
        <pose>0 0 0 0 0 0</pose>
        <geometry>
          <mesh>
            <uri>model://uarm/meshes/big_fore_arm_l.dae</uri>
          </mesh>
        </geometry>
      </visual>
      <self_collide>0</self_collide>
    </link>
    <link name="big_fore_arm_r">
      <pose>0 0 0 0 0 0</pose>
      <inertial>
        <mass>0.0276</mass>
        <pose> -0.023 0.01 0.2 0 0 0</pose>
        <inertia>
          <ixx>0.0051</ixx>
          <iyy>0.0051</iyy>
          <izz>0.0090</izz>
          <ixy>0</ixy>
          <ixz>0</ixz>
          <iyz>0</iyz>
        </inertia>
      </inertial>
      <collision name="collision">
        <pose>0 0 0 0 0 0</pose>
        <geometry>
          <mesh>
            <uri>model://uarm/meshes/big_fore_arm_r.dae</uri>
          </mesh>
        </geometry>
      </collision>
      <visual name="visual">
        <pose>0 0 0 0 0 0</pose>
        <geometry>
          <mesh>
            <uri>model://uarm/meshes/big_fore_arm_r.dae</uri>
          </mesh>
        </geometry>
      </visual>
      <self_collide>0</self_collide>
    </link>
    <link name="small_fore_arm">
      <pose>0 0 0 0 0 0</pose>
      <inertial>
        <mass>0.012</mass>
        <pose> -0.075 -0.028 0.21 0 0 0</pose>
        <inertia>
          <ixx>0.0051</ixx>
          <iyy>0.0051</iyy>
          <izz>0.0090</izz>
          <ixy>0</ixy>
          <ixz>0</ixz>
          <iyz>0</iyz>
        </inertia>
      </inertial>
      <collision name="collision">
        <pose>0 0 0 0 0 0</pose>
        <geometry>
          <mesh>
            <uri>model://uarm/meshes/small_fore_arm.dae</uri>
          </mesh>
        </geometry>
      </collision>
      <visual name="visual">
        <pose>0 0 0 0 0 0</pose>
        <geometry>
          <mesh>
            <uri>model://uarm/meshes/small_fore_arm.dae</uri>
          </mesh>
        </geometry>
      </visual>
      <self_collide>0</self_collide>
    </link>
    <link name="wrist_l">
      <pose>0 0 0 0 0 0</pose>
      <inertial>
        <mass>0.0084</mass>
        <pose> -0.147 -0.02 0.156 0 0 0</pose>
        <inertia>
          <ixx>0.0051</ixx>
          <iyy>0.0051</iyy>
          <izz>0.0090</izz>
          <ixy>0</ixy>
          <ixz>0</ixz>
          <iyz>0</iyz>
        </inertia>
      </inertial>
      <collision name="collision">
        <pose>0 0 0 0 0 0</pose>
        <geometry>
          <mesh>
            <uri>model://uarm/meshes/wrist_l.dae</uri>
          </mesh>
        </geometry>
      </collision>
      <visual name="visual">
        <pose>0 0 0 0 0 0</pose>
        <geometry>
          <mesh>
            <uri>model://uarm/meshes/wrist_l.dae</uri>
          </mesh>
        </geometry>
      </visual>
      <self_collide>0</self_collide>
    </link>
    <link name="wrist_r">
      <pose>0 0 0 0 0 0</pose>
      <inertial>
        <mass>0.0084</mass>
        <pose> -0.147 0 0.156 0 0 0</pose>
        <inertia>
          <ixx>0.0051</ixx>
          <iyy>0.0051</iyy>
          <izz>0.0090</izz>
          <ixy>0</ixy>
          <ixz>0</ixz>
          <iyz>0</iyz>
        </inertia>
      </inertial>
      <collision name="collision">
        <pose>0 0 0 0 0 0</pose>
        <geometry>
          <mesh>
            <uri>model://uarm/meshes/wrist_r.dae</uri>
          </mesh>
        </geometry>
      </collision>
      <visual name="visual">
        <pose>0 0 0 0 0 0</pose>
        <geometry>
          <mesh>
            <uri>model://uarm/meshes/wrist_r.dae</uri>
          </mesh>
        </geometry>
      </visual>
      <self_collide>0</self_collide>
    </link> 
    <link name='suction_cup'>
      <pose>-0.15 -0.0 0.14 0 0 0</pose>
      <inertial>
        <mass>0.005</mass>
        <inertia>
          <ixx>1</ixx>
          <ixy>1</ixy>
          <ixz>1</ixz>
          <iyy>1</iyy>
          <iyz>1</iyz>
          <izz>1</izz>
        </inertia>
      </inertial>
      <collision name='uarm_suction_cup_collison'>
        <geometry>
          <cylinder>
            <radius> 0.01 </radius>
            <length> 0.03 </length>
          </cylinder>
        </geometry>
      </collision>
      <visual name='visual'>
        <geometry>
          <cylinder>
            <radius> 0.01 </radius>
            <length> 0.03 </length>
          </cylinder>
        </geometry>
        <material>
          <script>
            <uri>file://media/materials/scripts/gazebo.material</uri>
            <name>Gazebo/Grey</name>
          </script>
        </material>
      </visual>
      
      <sensor name='uarm_box_contact' type='contact'>
          <plugin name="uarm_suction_cup_contact" filename="libuarm_suction_cup_contact.so"/>
          <contact>
            <collision>uarm_suction_cup_collison</collision>
          </contact>
      </sensor>    
      <self_collide>0</self_collide>
    </link>
    
    <!-- JOINTS ----------------------------------------------->
    <joint name="center_table_mount" type="revolute">
      <pose>0 0 0 0 0 0</pose>
      <child>base_center</child>
      <parent>table_link</parent>
      <axis>
        <xyz>0 0 1</xyz>
      </axis>
    </joint>
    <joint name="left_base_center_joint" type="revolute">
      <pose>0 0 0 0 0 0</pose>
      <child>base_l</child>
      <parent>base_center</parent>
      <axis>
        <xyz>0 0 1</xyz>
        <limit>
          <upper>0</upper>
          <lower>0</lower>
        </limit>
      </axis>
    </joint>
    <joint name="right_base_center_joint" type="revolute">
      <pose>0 0 0 0 0 0</pose>
      <child>base_r</child>
      <parent>base_center</parent>
      <axis>
        <xyz>0 0 1</xyz>
        <limit>
          <upper>0</upper>
          <lower>0</lower>
        </limit>
      </axis>
    </joint>
    <joint type="revolute" name="left_base_arm_joint">
      <pose> -0.019 0 0.078 0 0 0</pose>
      <child>big_under_arm_l</child>
      <parent>base_l</parent>
      <axis>
        <xyz>0 1 0</xyz>
      </axis>
    </joint>
    <joint type="revolute" name="right_base_arm_joint">
      <pose> -0.019 0 0.078 0 0 0</pose>
      <child>big_under_arm_r</child>
      <parent>big_under_arm_l</parent>
      <axis>
        <xyz>0 1 0</xyz>
        <limit>
          <upper>0</upper>
          <lower>0</lower>
        </limit>
      </axis>
    </joint>
    <joint type="revolute" name="left_base_shoulder_joint">
      <pose> -0.019 0 0.078 0 0 0</pose>
      <child>shoulder_l</child>
      <parent>base_l</parent>
      <axis>
        <xyz>0 1 0</xyz>
      </axis>
    </joint>
    <joint type="revolute" name="right_base_shoulder_joint">
      <pose> -0.019 0 0.078 0 0 0</pose>
      <child>shoulder_r</child>
      <parent>shoulder_l</parent>
      <axis>
        <xyz>0 1 0</xyz>
        <limit>
          <upper>0</upper>
          <lower>0</lower>
        </limit>
      </axis>
    </joint>
    <joint type="revolute" name="left_base_small_arm_joint">
      <pose> 0.015 -0.03 0.103 0 0 0</pose>
      <child>small_under_arm_l</child>
      <parent>base_l</parent>
      <axis>
        <xyz>0 1 0</xyz>
      </axis>
    </joint>
    <joint type="revolute" name="shoulder_arm_joint">
      <pose> 0.028 0.0 0.102 0 0 0</pose>
      <child>small_under_arm_r</child>
      <parent>shoulder_l</parent>
      <axis>
        <xyz>0 1 0</xyz>
      </axis>
    </joint>
    <joint type="revolute" name="elbow_big_under_arm_joint">
      <pose> 0.028 -0.02 0.2185 0 0 0</pose>
      <child>big_under_arm_l</child>
      <parent>elbow</parent>
      <axis>
        <xyz>0 1 0</xyz>
      </axis>
    </joint>
    <joint type="revolute" name="elbow_small_under_arm_joint">
      <pose> 0.062 -0.02 0.243 0 0 0</pose>
      <child>small_under_arm_l</child>
      <parent>elbow</parent>
      <axis>
        <xyz>0 1 0</xyz>
      </axis>
    </joint>
    <joint type="revolute" name="big_under_arm_fore_arm_joint">
      <pose> 0.028 -0.02 0.2185 0 0 0</pose>
      <child>big_fore_arm_l</child>
      <parent>big_under_arm_l</parent>
      <axis>
        <xyz>0 1 0</xyz>
      </axis>
    </joint>
    <joint type="revolute" name="small_under_arm_fore_arm_joint">
      <pose> 0.0765 0.0 0.2415 0 0 0</pose>
      <child>big_fore_arm_l</child>
      <parent>small_under_arm_r</parent>
      <axis>
        <xyz>0 1 0</xyz>
      </axis>
    </joint>
    <joint type="revolute" name="left_right_fore_arm_joint">
      <pose> 0.0765 0.0 0.2415 0 0 0</pose>
      <child>big_fore_arm_r</child>
      <parent>big_fore_arm_l</parent>
      <axis>
        <xyz>0 1 0</xyz>
        <limit>
          <upper>0</upper>
          <lower>0</lower>
        </limit>
      </axis>
    </joint>
    <joint type="revolute" name="elbow_fore_arm_joint">
      <pose> -0.007 -0.02 0.243 0 0 0</pose>
      <child>small_fore_arm</child>
      <parent>elbow</parent>
      <axis>
        <xyz>0 1 0</xyz>
      </axis>
    </joint>
    <joint type="revolute" name="small_fore_arm_wrist_joint">
      <pose> -0.1515 -0.02 0.1735 0 0 0</pose>
      <child>small_fore_arm</child>
      <parent>wrist_l</parent>
      <axis>
        <xyz>0 1 0</xyz>
      </axis>
    </joint>
    <joint type="revolute" name="left_right_wrist_joint">
      <pose> -0.1515 -0.02 0.1735 0 0 0</pose>
      <child>wrist_l</child>
      <parent>wrist_r</parent>
      <axis>
        <xyz>0 1 0</xyz>
        <limit>
          <upper>0</upper>
          <lower>0</lower>
        </limit>
      </axis>
    </joint>
    <joint type="revolute" name="big_fore_arm_wrist_joint">
      <pose> -0.117 -0.02 0.15 0 0 0</pose>
      <child>big_fore_arm_l</child>
      <parent>wrist_l</parent>
      <axis>
        <xyz>0 1 0</xyz>
      </axis>
    </joint>
    <joint type="revolute" name="suction_cup_wrist_joint">
      <pose> -0.14 -0.0 0.13 0 0 0</pose>
      <child>suction_cup</child>
      <parent>wrist_l</parent>
      <axis>
        <xyz>0 1 0</xyz>
        <limit>
          <upper>0</upper>
          <lower>0</lower>
        </limit>
      </axis>
    </joint>
    <!-- Load the controller plugin to control the joints of the portal robot ! -->  
    <plugin name="UarmController" filename="build/libUarmController.so"/>
    <plugin name="SuctionCup" filename="build/libsuction_cup.so"/>
  </model>
</sdf>
